Workbook

Sheet Flujo Completo Reprogramado
A1: Flujo Completo Mensual — Real + Reprogramado (Dic-2025 a Jul-2027)
A2: Bloque 1: presupuesto original (referencia, fuente Flujo_Araya_fase_I). Bloque 2: real ejecutado (Dic-25 a Jul-26) y proyección (Ago-26 a Jul-27, con la variación acumulada de Dic-25 a Jul-26 redistribuida solo en Ago-26 y Sep-26) — cierra en el total de RD$751,309,285.
A4: BLOQUE 1 — PRESUPUESTO ORIGINAL (referencia)
A5: Categoría | B5: Acum. Anterior | C5: Dic-25 | D5: Ene-26 | E5: Feb-26 | F5: Mar-26 | G5: Abr-26 | H5: May-26 | I5: Jun-26 | J5: Jul-26 | K5: Ago-26 | L5: Sep-26 | M5: Oct-26 | N5: Nov-26 | O5: Dic-26 | P5: Ene-27 | Q5: Feb-27 | R5: Mar-27 | S5: Abr-27 | T5: May-27 | U5: Jun-27 | V5: Jul-27 | W5: Ago-27 | X5: Sep-27 | Y5: Oct-27 | Z5: Nov-27 | AA5: Dic-27 | AB5: Ene-28 | AC5: Feb-28 | AD5: Mar-28 | AE5: Abr-28 | AF5: Total
A6: Instalaciones Preliminares | B6: 0 | C6: 330400 | D6: 128384 | E6: 1533833.6 | F6: 0 | G6: 0 | H6: 0 | I6: 0 | J6: 0 | K6: 0 | L6: 0 | M6: 0 | N6: 0 | O6: 0 | P6: 0 | Q6: 0 | R6: 0 | S6: 0 | T6: 0 | U6: 0 | V6: 0 | W6: 0 | X6: 0 | Y6: 0 | Z6: 0 | AA6: 0 | AB6: 0 | AC6: 0 | AD6: 0 | AE6: 0 | AF6: =SUM(B6,C6:AE6) -> 1992617.6
A7: Movimiento de Tierra | B7: 0 | C7: 0 | D7: 0 | E7: 0 | F7: 0 | G7: 1895547.6 | H7: 4597021 | I7: 4597021 | J7: 0 | K7: 0 | L7: 0 | M7: 0 | N7: 0 | O7: 0 | P7: 0 | Q7: 0 | R7: 0 | S7: 0 | T7: 0 | U7: 0 | V7: 0 | W7: 0 | X7: 0 | Y7: 0 | Z7: 0 | AA7: 0 | AB7: 0 | AC7: 0 | AD7: 0 | AE7: 0 | AF7: =SUM(B7,C7:AE7) -> 11089590
A8: Instalaciones Residual | B8: 0 | C8: 0 | D8: 0 | E8: 0 | F8: 0 | G8: 0 | H8: 0 | I8: 2456464.8 | J8: 1228232.4 | K8: 2456464.8 | L8: 3684697.2 | M8: 2456464.8 | N8: 0 | O8: 0 | P8: 0 | Q8: 0 | R8: 0 | S8: 0 | T8: 0 | U8: 0 | V8: 0 | W8: 0 | X8: 0 | Y8: 0 | Z8: 0 | AA8: 0 | AB8: 0 | AC8: 0 | AD8: 0 | AE8: 0 | AF8: =SUM(B8,C8:AE8) -> 12282324
A9: Instalaciones Pluvial | B9: 0 | C9: 0 | D9: 0 | E9: 0 | F9: 0 | G9: 0 | H9: 0 | I9: 0 | J9: 0 | K9: 1298558.4 | L9: 1298558.4 | M9: 2597116.8 | N9: 1298558.4 | O9: 0 | P9: 0 | Q9: 0 | R9: 0 | S9: 0 | T9: 0 | U9: 0 | V9: 0 | W9: 0 | X9: 0 | Y9: 0 | Z9: 0 | AA9: 0 | AB9: 0 | AC9: 0 | AD9: 0 | AE9: 0 | AF9: =SUM(B9,C9:AE9) -> 6492792
A10: Instalaciones Agua Potable | B10: 0 | C10: 0 | D10: 0 | E10: 0 | F10: 0 | G10: 0 | H10: 0 | I10: 0 | J10: 1005131.4 | K10: 1005131.4 | L10: 1507697.1 | M10: 1005131.4 | N10: 502565.69 | O10: 0 | P10: 0 | Q10: 0 | R10: 0 | S10: 0 | T10: 0 | U10: 0 | V10: 0 | W10: 0 | X10: 0 | Y10: 0 | Z10: 0 | AA10: 0 | AB10: 0 | AC10: 0 | AD10: 0 | AE10: 0 | AF10: =SUM(B10,C10:AE10) -> 5025656.9
A11: Pozo y Tanques | B11: 0 | C11: 0 | D11: 0 | E11: 0 | F11: 0 | G11: 0 | H11: 0 | I11: 0 | J11: 0 | K11: 3108517.7 | L11: 3108517.7 | M11: 6217035.4 | N11: 6217035.4 | O11: 6217035.4 | P11: 6183196.6 | Q11: 0 | R11: 0 | S11: 0 | T11: 0 | U11: 0 | V11: 0 | W11: 0 | X11: 0 | Y11: 0 | Z11: 0 | AA11: 0 | AB11: 0 | AC11: 0 | AD11: 0 | AE11: 0 | AF11: =SUM(B11,C11:AE11) -> 31051338
A12: Escalera | B12: 0 | C12: 0 | D12: 0 | E12: 0 | F12: 0 | G12: 0 | H12: 0 | I12: 0 | J12: 0 | K12: 0 | L12: 0 | M12: 0 | N12: 0 | O12: 0 | P12: 0 | Q12: 0 | R12: 0 | S12: 0 | T12: 0 | U12: 0 | V12: 0 | W12: 0 | X12: 0 | Y12: 0 | Z12: 0 | AA12: 0 | AB12: 0 | AC12: 0 | AD12: 0 | AE12: 0 | AF12: =SUM(B12,C12:AE12) -> 0
A13: Planta de Tratamiento | B13: 0 | C13: 0 | D13: 0 | E13: 0 | F13: 0 | G13: 0 | H13: 0 | I13: 4159815.1 | J13: 0 | K13: 1386605 | L13: 2773210 | M13: 2773210 | N13: 1386605 | O13: 1386605 | P13: 0 | Q13: 0 | R13: 0 | S13: 0 | T13: 0 | U13: 0 | V13: 0 | W13: 0 | X13: 0 | Y13: 0 | Z13: 0 | AA13: 0 | AB13: 0 | AC13: 0 | AD13: 0 | AE13: 0 | AF13: =SUM(B13,C13:AE13) -> 13866050
A14: Electrificacion y Telecom | B14: 0 | C14: 0 | D14: 0 | E14: 0 | F14: 0 | G14: 0 | H14: 0 | I14: 0 | J14: 0 | K14: 16627956 | L14: 6651182.3 | M14: 6651182.3 | N14: 6651182.3 | O14: 6651182.3 | P14: 6651182.3 | Q14: 6651182.3 | R14: 10242177 | S14: 0 | T14: 0 | U14: 0 | V14: 0 | W14: 0 | X14: 0 | Y14: 0 | Z14: 0 | AA14: 0 | AB14: 0 | AC14: 0 | AD14: 0 | AE14: 0 | AF14: =SUM(B14,C14:AE14) -> 66777227
A15: Vialidad y Gas | B15: 0 | C15: 0 | D15: 0 | E15: 0 | F15: 0 | G15: 0 | H15: 0 | I15: 0 | J15: 0 | K15: 0 | L15: 0 | M15: 3306411.3 | N15: 826602.81 | O15: 2479808.4 | P15: 826602.81 | Q15: 3306411.3 | R15: 1653205.6 | S15: 2479808.4 | T15: 2831079.6 | U15: 0 | V15: 0 | W15: 0 | X15: 0 | Y15: 0 | Z15: 0 | AA15: 0 | AB15: 0 | AC15: 0 | AD15: 0 | AE15: 0 | AF15: =SUM(B15,C15:AE15) -> 17709930
A16: Cocina | B16: 0 | C16: 0 | D16: 0 | E16: 0 | F16: 0 | G16: 0 | H16: 0 | I16: 0 | J16: 0 | K16: 0 | L16: 0 | M16: 0 | N16: 0 | O16: 0 | P16: 0 | Q16: 0 | R16: 0 | S16: 0 | T16: 0 | U16: 0 | V16: 0 | W16: 0 | X16: 0 | Y16: 0 | Z16: 0 | AA16: 0 | AB16: 0 | AC16: 0 | AD16: 0 | AE16: 0 | AF16: =SUM(B16,C16:AE16) -> 0
A17: Paisajismo | B17: 0 | C17: 0 | D17: 0 | E17: 0 | F17: 0 | G17: 0 | H17: 0 | I17: 0 | J17: 0 | K17: 0 | L17: 0 | M17: 0 | N17: 1796347.4 | O17: 718538.96 | P17: 1437077.9 | Q17: 1437077.9 | R17: 1437077.9 | S17: 359269.48 | T17: 1718806.8 | U17: 0 | V17: 0 | W17: 0 | X17: 0 | Y17: 0 | Z17: 0 | AA17: 0 | AB17: 0 | AC17: 0 | AD17: 0 | AE17: 0 | AF17: =SUM(B17,C17:AE17) -> 8904196.4
A18: Elementos Urbanos y Obras Ext. | B18: 0 | C18: 791187.8 | D18: 301404.37 | E18: 4265784.7 | F18: 688406.98 | G18: 0 | H18: 0 | I18: 0 | J18: 0 | K18: 0 | L18: 0 | M18: 5178434.3 | N18: 3452289.5 | O18: 5178434.3 | P18: 3452289.5 | Q18: 3452289.5 | R18: 6639957.6 | S18: 1122416.6 | T18: 4012087.9 | U18: 0 | V18: 0 | W18: 0 | X18: 0 | Y18: 0 | Z18: 0 | AA18: 0 | AB18: 0 | AC18: 0 | AD18: 0 | AE18: 0 | AF18: =SUM(B18,C18:AE18) -> 38534983
A19: TOTAL URBANISMO | B19: 22125480 | C19: =SUM(C6:C18) -> 1121587.8 | D19: =SUM(D6:D18) -> 429788.37 | E19: =SUM(E6:E18) -> 5799618.3 | F19: =SUM(F6:F18) -> 688406.98 | G19: =SUM(G6:G18) -> 1895547.6 | H19: =SUM(H6:H18) -> 4597021 | I19: =SUM(I6:I18) -> 11213301 | J19: =SUM(J6:J18) -> 2233363.8 | ... AE19: =SUM(AE6:AE18) -> 0 | AF19: =SUM(B19:AE19) -> 2.3585219e+08
A21: Excavaciones y Compactacion | B21: 0 | C21: 360773.79 | D21: 360773.79 | E21: 721547.59 | F21: 1443095.2 | G21: 1443095.2 | H21: 1443095.2 | I21: 1443095.2 | J21: 1443095.2 | K21: 721547.59 | L21: 0 | M21: 0 | N21: 0 | O21: 0 | P21: 0 | Q21: 0 | R21: 0 | S21: 0 | T21: 0 | U21: 0 | V21: 0 | W21: 0 | X21: 0 | Y21: 0 | Z21: 0 | AA21: 0 | AB21: 0 | AC21: 0 | AD21: 0 | AE21: 0 | AF21: =SUM(B21,C21:AE21) -> 9380118.6
A22: Acero en Platea | B22: 0 | C22: 446815.89 | D22: 446815.89 | E22: 893631.78 | F22: 1787263.6 | G22: 1787263.6 | H22: 1787263.6 | I22: 1787263.6 | J22: 1787263.6 | K22: 893631.78 | L22: 0 | M22: 0 | N22: 0 | O22: 0 | P22: 0 | Q22: 0 | R22: 0 | S22: 0 | T22: 0 | U22: 0 | V22: 0 | W22: 0 | X22: 0 | Y22: 0 | Z22: 0 | AA22: 0 | AB22: 0 | AC22: 0 | AD22: 0 | AE22: 0 | AF22: =SUM(B22,C22:AE22) -> 11617213
A23: Encofrado en Platea | B23: 0 | C23: 44847.285 | D23: 44847.285 | E23: 89694.569 | F23: 179389.14 | G23: 179389.14 | H23: 179389.14 | I23: 179389.14 | J23: 179389.14 | K23: 89694.569 | L23: 0 | M23: 0 | N23: 0 | O23: 0 | P23: 0 | Q23: 0 | R23: 0 | S23: 0 | T23: 0 | U23: 0 | V23: 0 | W23: 0 | X23: 0 | Y23: 0 | Z23: 0 | AA23: 0 | AB23: 0 | AC23: 0 | AD23: 0 | AE23: 0 | AF23: =SUM(B23,C23:AE23) -> 1166029.4
A24: Concreto en Platea | B24: 0 | C24: 534800.56 | D24: 534800.56 | E24: 1069601.1 | F24: 2139202.2 | G24: 2139202.2 | H24: 2139202.2 | I24: 2139202.2 | J24: 2139202.2 | K24: 1069601.1 | L24: 0 | M24: 0 | N24: 0 | O24: 0 | P24: 0 | Q24: 0 | R24: 0 | S24: 0 | T24: 0 | U24: 0 | V24: 0 | W24: 0 | X24: 0 | Y24: 0 | Z24: 0 | AA24: 0 | AB24: 0 | AC24: 0 | AD24: 0 | AE24: 0 | AF24: =SUM(B24,C24:AE24) -> 13904815
A25: Concreto en Molde | B25: 0 | C25: 0 | D25: 0 | E25: 79839.163 | F25: 958069.96 | G25: 2475014.1 | H25: 3353244.9 | I25: 4790349.8 | J25: 4950028.1 | K25: 6227454.8 | L25: 4790349.8 | M25: 4790349.8 | N25: 4790349.8 | O25: 4311314.8 | P25: 0 | Q25: 0 | R25: 0 | S25: 0 | T25: 0 | U25: 0 | V25: 0 | W25: 0 | X25: 0 | Y25: 0 | Z25: 0 | AA25: 0 | AB25: 0 | AC25: 0 | AD25: 0 | AE25: 0 | AF25: =SUM(B25,C25:AE25) -> 41516365
A26: Encofrado en Molde | B26: 0 | C26: 0 | D26: 0 | E26: 344766.8 | F26: 1379067.2 | G26: 2413367.6 | H26: 3447668 | I26: 4137201.6 | J26: 4826735.2 | K26: 4826735.2 | L26: 4137201.6 | M26: 4137201.6 | N26: 4137201.6 | O26: 2068600.8 | P26: 0 | Q26: 0 | R26: 0 | S26: 0 | T26: 0 | U26: 0 | V26: 0 | W26: 0 | X26: 0 | Y26: 0 | Z26: 0 | AA26: 0 | AB26: 0 | AC26: 0 | AD26: 0 | AE26: 0 | AF26: =SUM(B26,C26:AE26) -> 35855747
A27: Acero en Superestructura | B27: 0 | C27: 0 | D27: 0 | E27: 333722.19 | F27: 1668611 | G27: 2669777.5 | H27: 3670944.1 | I27: 4004666.3 | J27: 4672110.7 | K27: 4672110.7 | L27: 4004666.3 | M27: 4004666.3 | N27: 4004666.3 | O27: 1001166.6 | P27: 0 | Q27: 0 | R27: 0 | S27: 0 | T27: 0 | U27: 0 | V27: 0 | W27: 0 | X27: 0 | Y27: 0 | Z27: 0 | AA27: 0 | AB27: 0 | AC27: 0 | AD27: 0 | AE27: 0 | AF27: =SUM(B27,C27:AE27) -> 34707108
A28: Instalaciones Electricas | B28: 0 | C28: 0 | D28: 0 | E28: 88641.51 | F28: 354566.04 | G28: 620490.57 | H28: 886415.1 | I28: 1063698.1 | J28: 1240981.1 | K28: 1240981.1 | L28: 1063698.1 | M28: 1063698.1 | N28: 1063698.1 | O28: 531849.06 | P28: 0 | Q28: 0 | R28: 0 | S28: 0 | T28: 0 | U28: 0 | V28: 0 | W28: 0 | X28: 0 | Y28: 0 | Z28: 0 | AA28: 0 | AB28: 0 | AC28: 0 | AD28: 0 | AE28: 0 | AF28: =SUM(B28,C28:AE28) -> 9218717
A29: Aguas Blancas | B29: 0 | C29: 0 | D29: 0 | E29: 58435.092 | F29: 233740.37 | G29: 409045.65 | H29: 584350.93 | I29: 701221.11 | J29: 818091.3 | K29: 818091.3 | L29: 701221.11 | M29: 701221.11 | N29: 701221.11 | O29: 350610.55 | P29: 0 | Q29: 0 | R29: 0 | S29: 0 | T29: 0 | U29: 0 | V29: 0 | W29: 0 | X29: 0 | Y29: 0 | Z29: 0 | AA29: 0 | AB29: 0 | AC29: 0 | AD29: 0 | AE29: 0 | AF29: =SUM(B29,C29:AE29) -> 6077249.6
A30: Aguas Residuales | B30: 0 | C30: 0 | D30: 0 | E30: 64617.03 | F30: 258468.12 | G30: 452319.21 | H30: 646170.3 | I30: 775404.36 | J30: 904638.42 | K30: 904638.42 | L30: 775404.36 | M30: 775404.36 | N30: 775404.36 | O30: 387702.18 | P30: 0 | Q30: 0 | R30: 0 | S30: 0 | T30: 0 | U30: 0 | V30: 0 | W30: 0 | X30: 0 | Y30: 0 | Z30: 0 | AA30: 0 | AB30: 0 | AC30: 0 | AD30: 0 | AE30: 0 | AF30: =SUM(B30,C30:AE30) -> 6720171.1
A31: Gas | B31: 0 | C31: 0 | D31: 0 | E31: 16494.715 | F31: 65978.86 | G31: 115463.01 | H31: 164947.15 | I31: 197936.58 | J31: 230926.01 | K31: 230926.01 | L31: 197936.58 | M31: 197936.58 | N31: 197936.58 | O31: 98968.29 | P31: 0 | Q31: 0 | R31: 0 | S31: 0 | T31: 0 | U31: 0 | V31: 0 | W31: 0 | X31: 0 | Y31: 0 | Z31: 0 | AA31: 0 | AB31: 0 | AC31: 0 | AD31: 0 | AE31: 0 | AF31: =SUM(B31,C31:AE31) -> 1715450.4
A32: Albañileria | B32: 0 | C32: 0 | D32: 0 | E32: 0 | F32: 0 | G32: 2658473.8 | H32: 2658473.8 | I32: 2658473.8 | J32: 2658473.8 | K32: 2658473.8 | L32: 2658473.8 | M32: 2658473.8 | N32: 2658473.8 | O32: 1772315.9 | P32: 0 | Q32: 0 | R32: 0 | S32: 0 | T32: 0 | U32: 0 | V32: 0 | W32: 0 | X32: 0 | Y32: 0 | Z32: 0 | AA32: 0 | AB32: 0 | AC32: 0 | AD32: 0 | AE32: 0 | AF32: =SUM(B32,C32:AE32) -> 23040106
... A44: Remates y Limpieza | B44: 0 | C44: 0 | D44: 0 | E44: 0 | F44: 0 | G44: 0 | H44: 0 | I44: 0 | J44: 0 | K44: 0 | L44: 347981.54 | M44: 521972.31 | N44: 521972.31 | O44: 521972.31 | P44: 521972.31 | Q44: 521972.31 | R44: 521972.31 | S44: 521972.31 | T44: 260986.15 | U44: 260986.15 | V44: 0 | W44: 0 | X44: 0 | Y44: 0 | Z44: 0 | AA44: 0 | AB44: 0 | AC44: 0 | AD44: 0 | AE44: 0 | AF44: =SUM(B44,C44:AE44) -> 4523760
A45: TOTAL EDIFICIOS | B45: 0 | C45: =SUM(C21:C44) -> 1387237.5 | D45: =SUM(D21:D44) -> 1387237.5 | E45: =SUM(E21:E44) -> 3798163.3 | F45: =SUM(F21:F44) -> 11925251 | G45: =SUM(G21:G44) -> 29783110 | H45: =SUM(H21:H44) -> 38576638 | I45: =SUM(I21:I44) -> 68677665 | J45: =SUM(J21:J44) -> 42068379 | ... AE45: =SUM(AE21:AE44) -> 0 | AF45: =SUM(B45:AE45) -> 5.154571e+08
A47: TOTAL GENERAL | B47: =B19+B45 -> 22125480 | C47: =C19+C45 -> 2508825.3 | D47: =D19+D45 -> 1817025.9 | E47: =E19+E45 -> 9597781.6 | F47: =F19+F45 -> 12613658 | G47: =G19+G45 -> 31678657 | H47: =H19+H45 -> 43173659 | I47: =I19+I45 -> 79890966 | ... AF47: =AF19+AF45 -> 7.5130928e+08
A49: BLOQUE 2 — REAL EJECUTADO (Dic-25 a Jul-26) + REPROGRAMADO (Ago-26 a Jul-27)
A50: Categoría | B50: Acum. Anterior | C50: Dic-25 | D50: Ene-26 | E50: Feb-26 | F50: Mar-26 | G50: Abr-26 | H50: May-26 | I50: Jun-26 | J50: Jul-26 | K50: Ago-26 | L50: Sep-26 | M50: Oct-26 | N50: Nov-26 | O50: Dic-26 | P50: Ene-27 | Q50: Feb-27 | R50: Mar-27 | S50: Abr-27 | T50: May-27 | U50: Jun-27 | V50: Jul-27 | W50: Ago-27 | X50: Sep-27 | Y50: Oct-27 | Z50: Nov-27 | AA50: Dic-27 | AB50: Ene-28 | AC50: Feb-28 | AD50: Mar-28 | AE50: Abr-28 | AF50: Total
A51: Instalaciones Preliminares | B51: 0 | C51: =IFERROR(C6*'Comparación Mensual'!C5/C19,0) -> 4538721 | D51: =IFERROR(D6*'Comparación Mensual'!C6/D19,0) -> 66566.996 | E51: =IFERROR(E6*'Comparación Mensual'!C7/E19,0) -> 647841.35 | F51: =IFERROR(F6*'Comparación Mensual'!C8/F19,0) -> 0 | G51: =IFERROR(G6*'Comparación Mensual'!C9/G19,0) -> 0 | H51: =IFERROR(H6*'Comparación Mensual'!C10/H19,0) -> 0 | I51: =IFERROR(I6*'Comparación Mensual'!C11/I19,0) -> 0 | J51: =IFERROR(J6*'Comparación Mensual'!C12/J19,0) -> 0 | K51: =K6*Reprogramación!$C$14/Reprogramación!$B$14 -> 0 | L51: =L6*Reprogramación!$C$15/Reprogramación!$B$15 -> 0 | M51: =M6 -> 0 | N51: =N6 -> 0 | O51: =O6 -> 0 | P51: =P6 -> 0 | Q51: =Q6 -> 0 | R51: =R6 -> 0 | S51: =S6 -> 0 | T51: =T6 -> 0 | ... V51: =V6 -> 0 | W51: 0 | X51: 0 | Y51: 0 | Z51: 0 | AA51: 0 | AB51: 0 | AC51: 0 | AD51: 0 | AE51: 0 | AF51: =SUM(B51,C51:AE51) -> 5253129.3
A52: Movimiento de Tierra | B52: 0 | C52: =IFERROR(C7*'Comparación Mensual'!C5/C19,0) -> 0 | D52: =IFERROR(D7*'Comparación Mensual'!C6/D19,0) -> 0 | E52: =IFERROR(E7*'Comparación Mensual'!C7/E19,0) -> 0 | F52: =IFERROR(F7*'Comparación Mensual'!C8/F19,0) -> 0 | G52: =IFERROR(G7*'Comparación Mensual'!C9/G19,0) -> 2442502.3 | H52: =IFERROR(H7*'Comparación Mensual'!C10/H19,0) -> 4340947.8 | I52: =IFERROR(I7*'Comparación Mensual'!C11/I19,0) -> 2244901.6 | J52: =IFERROR(J7*'Comparación Mensual'!C12/J19,0) -> 0 | K52: =K7*Reprogramación!$C$14/Reprogramación!$B$14 -> 0 | L52: =L7*Reprogramación!$C$15/Reprogramación!$B$15 -> 0 | M52: =M7 -> 0 | N52: =N7 -> 0 | O52: =O7 -> 0 | P52: =P7 -> 0 | Q52: =Q7 -> 0 | R52: =R7 -> 0 | S52: =S7 -> 0 | T52: =T7 -> 0 | ... V52: =V7 -> 0 | W52: 0 | X52: 0 | Y52: 0 | Z52: 0 | AA52: 0 | AB52: 0 | AC52: 0 | AD52: 0 | AE52: 0 | AF52: =SUM(B52,C52:AE52) -> 9028351.8
A53: Instalaciones Residual | B53: 0 | C53: =IFERROR(C8*'Comparación Mensual'!C5/C19,0) -> 0 | D53: =IFERROR(D8*'Comparación Mensual'!C6/D19,0) -> 0 | E53: =IFERROR(E8*'Comparación Mensual'!C7/E19,0) -> 0 | F53: =IFERROR(F8*'Comparación Mensual'!C8/F19,0) -> 0 | G53: =IFERROR(G8*'Comparación Mensual'!C9/G19,0) -> 0 | H53: =IFERROR(H8*'Comparación Mensual'!C10/H19,0) -> 0 | I53: =IFERROR(I8*'Comparación Mensual'!C11/I19,0) -> 1199586 | J53: =IFERROR(J8*'Comparación Mensual'!C12/J19,0) -> 4468464.1 | K53: =K8*Reprogramación!$C$14/Reprogramación!$B$14 -> 1871864.9 | L53: =L8*Reprogramación!$C$15/Reprogramación!$B$15 -> 2491616.5 | M53: =M8 -> 2456464.8 | N53: =N8 -> 0 | O53: =O8 -> 0 | P53: =P8 -> 0 | Q53: =Q8 -> 0 | R53: =R8 -> 0 | S53: =S8 -> 0 | T53: =T8 -> 0 | ... V53: =V8 -> 0 | W53: 0 | X53: 0 | Y53: 0 | Z53: 0 | AA53: 0 | AB53: 0 | AC53: 0 | AD53: 0 | AE53: 0 | AF53: =SUM(B53,C53:AE53) -> 12487996
A54: Instalaciones Pluvial | B54: 0 | C54: =IFERROR(C9*'Comparación Mensual'!C5/C19,0) -> 0 | D54: =IFERROR(D9*'Comparación Mensual'!C6/D19,0) -> 0 | E54: =IFERROR(E9*'Comparación Mensual'!C7/E19,0) -> 0 | F54: =IFERROR(F9*'Comparación Mensual'!C8/F19,0) -> 0 | G54: =IFERROR(G9*'Comparación Mensual'!C9/G19,0) -> 0 | H54: =IFERROR(H9*'Comparación Mensual'!C10/H19,0) -> 0 | I54: =IFERROR(I9*'Comparación Mensual'!C11/I19,0) -> 0 | J54: =IFERROR(J9*'Comparación Mensual'!C12/J19,0) -> 0 | K54: =K9*Reprogramación!$C$14/Reprogramación!$B$14 -> 989521.96 | L54: =L9*Reprogramación!$C$15/Reprogramación!$B$15 -> 878093.73 | M54: =M9 -> 2597116.8 | N54: =N9 -> 1298558.4 | O54: =O9 -> 0 | P54: =P9 -> 0 | Q54: =Q9 -> 0 | R54: =R9 -> 0 | S54: =S9 -> 0 | T54: =T9 -> 0 | ... V54: =V9 -> 0 | W54: 0 | X54: 0 | Y54: 0 | Z54: 0 | AA54: 0 | AB54: 0 | AC54: 0 | AD54: 0 | AE54: 0 | AF54: =SUM(B54,C54:AE54) -> 5763290.9
A55: Instalaciones Agua Potable | B55: 0 | C55: =IFERROR(C10*'Comparación Mensual'!C5/C19,0) -> 0 | D55: =IFERROR(D10*'Comparación Mensual'!C6/D19,0) -> 0 | E55: =IFERROR(E10*'Comparación Mensual'!C7/E19,0) -> 0 | F55: =IFERROR(F10*'Comparación Mensual'!C8/F19,0) -> 0 | G55: =IFERROR(G10*'Comparación Mensual'!C9/G19,0) -> 0 | H55: =IFERROR(H10*'Comparación Mensual'!C10/H19,0) -> 0 | I55: =IFERROR(I10*'Comparación Mensual'!C11/I19,0) -> 0 | J55: =IFERROR(J10*'Comparación Mensual'!C12/J19,0) -> 3656794.5 | K55: =K10*Reprogramación!$C$14/Reprogramación!$B$14 -> 765925.95 | L55: =L10*Reprogramación!$C$15/Reprogramación!$B$15 -> 1019514.7 | M55: =M10 -> 1005131.4 | N55: =N10 -> 502565.69 | O55: =O10 -> 0 | P55: =P10 -> 0 | Q55: =Q10 -> 0 | R55: =R10 -> 0 | S55: =S10 -> 0 | T55: =T10 -> 0 | ... V55: =V10 -> 0 | W55: 0 | X55: 0 | Y55: 0 | Z55: 0 | AA55: 0 | AB55: 0 | AC55: 0 | AD55: 0 | AE55: 0 | AF55: =SUM(B55,C55:AE55) -> 6949932.1
...

Sheet Resumen
A1: ARAYA Fase I — Comparación Flujo Presupuestado vs. Gasto Real
A2: Periodo analizado: Dic-2025 a Jul-2026 · Fuente: Flujo semanal (proyectado) y Mayor de Cuentas (real)
A4: Concepto | B4: Presupuestado | C4: Real | D4: Variación | E4: Variación %
A5: Urbanismo (Dic-25 a Jul-26) | B5: 27978635 | C5: 40298238 | D5: =B5-C5 -> -12319603 | E5: =IFERROR(D5/B5,0) -> -0.44032182
A6: Edificios (Dic-25 a Jul-26) | B6: 1.9760368e+08 | C6: 1.1460928e+08 | D6: =B6-C6 -> 82994397 | E6: =IFERROR(D6/B6,0) -> 0.42000431
A7: TOTAL | B7: =SUM(B5:B6) -> 2.2558232e+08 | C7: =SUM(C5:C6) -> 1.5490752e+08 | D7: =B7-C7 -> 70674794 | E7: =IFERROR(D7/B7,0) -> 0.31329936
A9: Lectura del periodo
A10: • Urbanismo gastó RD$40.3M reales contra RD$28.0M presupuestados (Dic-25 a Jul-26) — un sobregiro de ~RD$12.3M, explicado principalmente por el pago adelantado del contrato de Movimiento de Tierra en diciembre 2025. En julio, Urbanismo también se sobregiró (RD$8.1M reales vs RD$2.2M presupuestados), por el arranque de partidas de infraestructura pendientes.
A11: • Edificios gastó RD$114.6M reales contra RD$197.6M presupuestados — un remanente de ~RD$83.0M no ejecutado, consistente con los atrasos de estructura y acabados. En julio el remanente individual fue de ~RD$18.5M.
A12: • Reprogramación de julio: la variación acumulada real de Dic-25 a Jul-26 (Urbanismo y Edificios) se redistribuyó íntegramente entre agosto y septiembre 2026 (mitad y mitad por categoría), sin modificar el resto del flujo futuro. Ver hoja "Reprogramación".
A13: • Los gastos de Terreno, Diseño, Gerencia de Construcción, Indirectos, Inspección Técnica, Permisos y Gastos Financieros no forman parte del flujo de obra analizado; se excluyen de esta comparación por estar fuera del alcance de Urbanismo/Edificios.

Sheet Comparación Mensual
A1: Comparación Mensual — Presupuestado vs. Real
A2: Urbanismo y Edificios · Dic-2025 a Jul-2026
A4: Mes | B4: Urb. Presupuestado | C4: Urb. Real | D4: Urb. Variación | E4: Urb. Var. Acum. | F4: Edi. Presupuestado | G4: Edi. Real | H4: Edi. Variación | I4: Edi. Var. Acum. | J4: Total Presupuestado | K4: Total Real | L4: Total Variación
A5: Dic-25 | B5: 1121587.8 | C5: 15407306 | D5: =B5-C5 -> -14285719 | E5: =D5 -> -14285719 | F5: 1387237.5 | G5: 991237.18 | H5: =F5-G5 -> 396000.35 | I5: =H5 -> 396000.35 | J5: =B5+F5 -> 2508825.3 | K5: =C5+G5 -> 16398544 | L5: =J5-K5 -> -13889718
A6: Ene-26 | B6: 429788.37 | C6: 222844.91 | D6: =B6-C6 -> 206943.46 | E6: =E5+D6 -> -14078775 | F6: 1387237.5 | G6: 2132656.5 | H6: =F6-G6 -> -745418.92 | I6: =I5+H6 -> -349418.57 | J6: =B6+F6 -> 1817025.9 | K6: =C6+G6 -> 2355501.4 | L6: =J6-K6 -> -538475.46
A7: Feb-26 | B7: 5799618.3 | C7: 2449569.8 | D7: =B7-C7 -> 3350048.5 | E7: =E6+D7 -> -10728727 | F7: 3798163.3 | G7: 6421897.4 | H7: =F7-G7 -> -2623734.1 | I7: =I6+H7 -> -2973152.7 | J7: =B7+F7 -> 9597781.6 | K7: =C7+G7 -> 8871467.3 | L7: =J7-K7 -> 726314.35
A8: Mar-26 | B8: 688406.98 | C8: 1833923.4 | D8: =B8-C8 -> -1145516.4 | E8: =E7+D8 -> -11874243 | F8: 11925251 | G8: 23623624 | H8: =F8-G8 -> -11698373 | I8: =I7+H8 -> -14671525 | J8: =B8+F8 -> 12613658 | K8: =C8+G8 -> 25457547 | L8: =J8-K8 -> -12843889
A9: Abr-26 | B9: 1895547.6 | C9: 2442502.3 | D9: =B9-C9 -> -546954.75 | E9: =E8+D9 -> -12421198 | F9: 29783110 | G9: 17452542 | H9: =F9-G9 -> 12330568 | I9: =I8+H9 -> -2340957.3 | J9: =B9+F9 -> 31678657 | K9: =C9+G9 -> 19895044 | L9: =J9-K9 -> 11783613
A10: May-26 | B10: 4597021 | C10: 4340947.8 | D10: =B10-C10 -> 256073.19 | E10: =E9+D10 -> -12165125 | F10: 38576638 | G10: 17043612 | H10: =F10-G10 -> 21533025 | I10: =I9+H10 -> 19192068 | J10: =B10+F10 -> 43173659 | K10: =C10+G10 -> 21384560 | L10: =J10-K10 -> 21789098
A11: Jun-26 | B11: 11213301 | C11: 5475884.7 | D11: =B11-C11 -> 5737416.2 | E11: =E10+D11 -> -6427708.6 | F11: 68677665 | G11: 23333677 | H11: =F11-G11 -> 45343989 | I11: =I10+H11 -> 64536057 | J11: =B11+F11 -> 79890966 | K11: =C11+G11 -> 28809561 | L11: =J11-K11 -> 51081405
A12: Jul-26 | B12: 2233363.8 | C12: 8125258.5 | D12: =B12-C12 -> -5891894.8 | E12: =E11+D12 -> -12319603 | F12: 42068379 | G12: 23610038 | H12: =F12-G12 -> 18458341 | I12: =I11+H12 -> 82994397 | J12: =B12+F12 -> 44301743 | K12: =C12+G12 -> 31735297 | L12: =J12-K12 -> 12566446
A13: TOTAL | B13: =SUM(B5:B12) -> 27978635 | C13: =SUM(C5:C12) -> 40298238 | D13: =B13-C13 -> -12319603 | E13: =E12 -> -12319603 | F13: =SUM(F5:F12) -> 1.9760368e+08 | G13: =SUM(G5:G12) -> 1.1460928e+08 | H13: =F13-G13 -> 82994397 | I13: =I12 -> 82994397 | J13: =B13+F13 -> 2.2558232e+08 | K13: =C13+G13 -> 1.5490752e+08 | L13: =J13-K13 -> 70674794
A14: Nota: "Var. Acum." es la variación (Presupuestado − Real) acumulada mes a mes; positivo = remanente sin ejecutar, negativo = sobregiro frente al plan.

Sheet Reprogramación
A1: Reprogramación de Julio (Ago-2026 a Jul-2027)
A2: Metodología: junio y julio ya son reales (fuente: Costos_Araya_Dic-25_a_Jun-26.xlsx y Datos_para_informe_Julio_2026.xlsx). La variación acumulada de todo el periodo real (Dic-25 a Jul-26 vs. presupuesto original de esos mismos meses) se redistribuye únicamente entre Ago-26 y Sep-26 (mitad y mitad), de forma que el total reprogramado cierre exacto en el presupuesto total del proyecto. El resto de los meses futuros conserva su presupuesto original sin reescalar.
A4: URBANISMO
A5: Total Proyección (presupuesto total del proyecto) | B5: 2.3585219e+08
A6: Acumulado real anterior a Dic-2025 (según flujo) | B6: 22125480
A7: Real ejecutado Dic-25 a Jul-26 | B7: 40298238
A8: Real total acumulado a la fecha | B8: =B6+B7 -> 62423718
A9: Restante a distribuir (Ago-26 a Jul-27, informativo) | B9: =B5-B8 -> 1.7342847e+08
A11: Mes | B11: Presupuesto Original | C11: Presupuesto Reprogramado | D11: Diferencia
A12: Jun-26 | B12: 11213301 | C12: 5475884.7 | D12: =C12-B12 -> -5737416.2
A13: Jul-26 | B13: 2233363.8 | C13: 8125258.5 | D13: =C13-B13 -> 5891894.8
A14: Ago-26 | B14: 25883233 | C14: =B14+($B$9-SUM($B$14:$B$25))/2 -> 19723431 | D14: =C14-B14 -> -6159801.7
A15: Sep-26 | B15: 19023863 | C15: =B15+($B$9-SUM($B$14:$B$25))/2 -> 12864061 | D15: =C15-B15 -> -6159801.7
A16: Oct-26 | B16: 30184986 | C16: =B16 -> 30184986 | D16: =C16-B16 -> 0
A17: Nov-26 | B17: 22131187 | C17: =B17 -> 22131187 | D17: =C17-B17 -> 0
A18: Dic-26 | B18: 22631604 | C18: =B18 -> 22631604 | D18: =C18-B18 -> 0
A19: Ene-27 | B19: 18550349 | C19: =B19 -> 18550349 | D19: =C19-B19 -> 0
A20: Feb-27 | B20: 14846961 | C20: =B20 -> 14846961 | D20: =C20-B20 -> 0
A21: Mar-27 | B21: 19972418 | C21: =B21 -> 19972418 | D21: =C21-B21 -> 0
A22: Abr-27 | B22: 3961494.6 | C22: =B22 -> 3961494.6 | D22: =C22-B22 -> 0
A23: May-27 | B23: 8561974.3 | C23: =B23 -> 8561974.3 | D23: =C23-B23 -> 0
A24: Jun-27 | B24: 0 | C24: =B24 -> 0 | D24: =C24-B24 -> 0
A25: Jul-27 | B25: 0 | C25: =B25 -> 0 | D25: =C25-B25 -> 0
A26: SUMA (Jun-26 y Jul-26 real + Ago-26 a Jul-27 reprogramado) | B26: =SUM(B12:B25) -> 1.9919474e+08 | C26: =SUM(C12:C25) -> 1.8702961e+08
A27: Variación acumulada Dic-25 a Jul-26 redistribuida (Ago-26 + Sep-26) | B27: =$B$9-SUM($B$14:$B$25) -> -12319603
A28: Verificación: Real acum. a la fecha + Reprogramado (Ago-26 a Jul-27) = Total Proyección | B28: =B8+SUM(C14:C25) -> 2.3585219e+08 | C28: =B5 -> 2.3585219e+08 | D28: =B28-C28 -> 0
A30: EDIFICIOS
A31: Total Proyección (presupuesto total del proyecto) | B31: 5.154571e+08
A32: Acumulado real anterior a Dic-2025 (según flujo) | B32: 0
A33: Real ejecutado Dic-25 a Jul-26 | B33: 1.1460928e+08
A34: Real total acumulado a la fecha | B34: =B32+B33 -> 1.1460928e+08
A35: Restante a distribuir (Ago-26 a Jul-27, informativo) | B35: =B31-B34 -> 4.0084782e+08
A37: Mes | B37: Presupuesto Original | C37: Presupuesto Reprogramado | D37: Diferencia
A38: Jun-26 | B38: 68677665 | C38: 23333677 | D38: =C38-B38 -> -45343989
A39: Jul-26 | B39: 42068379 | C39: 23610038 | D39: =C39-B39 -> -18458341
A40: Ago-26 | B40: 51036207 | C40: =B40+($B$35-SUM($B$40:$B$51))/2 -> 92533406 | D40: =C40-B40 -> 41497199
A41: Sep-26 | B41: 59249226 | C41: =B41+($B$35-SUM($B$40:$B$51))/2 -> 1.0074642e+08 | D41: =C41-B41 -> 41497199
A42: Oct-26 | B42: 42294888 | C42: =B42 -> 42294888 | D42: =C42-B42 -> 0
A43: Nov-26 | B43: 48393363 | C43: =B43 -> 48393363 | D43: =C43-B43 -> 0
A44: Dic-26 | B44: 39868292 | C44: =B44 -> 39868292 | D44: =C44-B44 -> 0
...

Sheet Detalle Presupuesto x Categoría
A1: Detalle del Flujo Presupuestado por Categoría (Dic-25 a May-26)
A2: Fuente: Flujo_Araya_fase_I. Solo disponible a nivel de categoría en el presupuesto — el gasto real del mayor contable solo distingue Urbanismo vs. Edificios en conjunto.
A4: Categoría | B4: Dic-25 | C4: Ene-26 | D4: Feb-26 | E4: Mar-26 | F4: Abr-26 | G4: May-26 | H4: Total Periodo
A5: URBANISMO
A6: Instalaciones Preliminares | B6: 330400 | C6: 128384 | D6: 1533833.6 | E6: 0 | F6: 0 | G6: 0 | H6: =SUM(B6:G6) -> 1992617.6
A7: Movimiento de Tierra | B7: 0 | C7: 0 | D7: 0 | E7: 0 | F7: 1895547.6 | G7: 4597021 | H7: =SUM(B7:G7) -> 6492568.6
A8: Instalaciones Residual | B8: 0 | C8: 0 | D8: 0 | E8: 0 | F8: 0 | G8: 0 | H8: =SUM(B8:G8) -> 0
A9: Instalaciones Pluvial | B9: 0 | C9: 0 | D9: 0 | E9: 0 | F9: 0 | G9: 0 | H9: =SUM(B9:G9) -> 0
A10: Instalaciones Agua Potable | B10: 0 | C10: 0 | D10: 0 | E10: 0 | F10: 0 | G10: 0 | H10: =SUM(B10:G10) -> 0
A11: Pozo y Tanques | B11: 0 | C11: 0 | D11: 0 | E11: 0 | F11: 0 | G11: 0 | H11: =SUM(B11:G11) -> 0
A12: Escalera | B12: 0 | C12: 0 | D12: 0 | E12: 0 | F12: 0 | G12: 0 | H12: =SUM(B12:G12) -> 0
A13: Planta de Tratamiento | B13: 0 | C13: 0 | D13: 0 | E13: 0 | F13: 0 | G13: 0 | H13: =SUM(B13:G13) -> 0
A14: Electrificacion y Telecom | B14: 0 | C14: 0 | D14: 0 | E14: 0 | F14: 0 | G14: 0 | H14: =SUM(B14:G14) -> 0
A15: Vialidad y Gas | B15: 0 | C15: 0 | D15: 0 | E15: 0 | F15: 0 | G15: 0 | H15: =SUM(B15:G15) -> 0
A16: Cocina | B16: 0 | C16: 0 | D16: 0 | E16: 0 | F16: 0 | G16: 0 | H16: =SUM(B16:G16) -> 0
A17: Paisajismo | B17: 0 | C17: 0 | D17: 0 | E17: 0 | F17: 0 | G17: 0 | H17: =SUM(B17:G17) -> 0
A18: Elementos Urbanos y Obras Ext. | B18: 791187.8 | C18: 301404.37 | D18: 4265784.7 | E18: 688406.98 | F18: 0 | G18: 0 | H18: =SUM(B18:G18) -> 6046783.8
A19: TOTAL URBANISMO | B19: =SUM(B6:B18) -> 1121587.8 | C19: =SUM(C6:C18) -> 429788.37 | D19: =SUM(D6:D18) -> 5799618.3 | E19: =SUM(E6:E18) -> 688406.98 | F19: =SUM(F6:F18) -> 1895547.6 | G19: =SUM(G6:G18) -> 4597021 | H19: =SUM(H6:H18) -> 14531970
A21: EDIFICIOS
A22: Excavaciones y Compactacion | B22: 360773.79 | C22: 360773.79 | D22: 721547.59 | E22: 1443095.2 | F22: 1443095.2 | G22: 1443095.2 | H22: =SUM(B22:G22) -> 5772380.7
A23: Acero en Platea | B23: 446815.89 | C23: 446815.89 | D23: 893631.78 | E23: 1787263.6 | F23: 1787263.6 | G23: 1787263.6 | H23: =SUM(B23:G23) -> 7149054.2
A24: Encofrado en Platea | B24: 44847.285 | C24: 44847.285 | D24: 89694.569 | E24: 179389.14 | F24: 179389.14 | G24: 179389.14 | H24: =SUM(B24:G24) -> 717556.55
A25: Concreto en Platea | B25: 534800.56 | C25: 534800.56 | D25: 1069601.1 | E25: 2139202.2 | F25: 2139202.2 | G25: 2139202.2 | H25: =SUM(B25:G25) -> 8556809
A26: Concreto en Molde | B26: 0 | C26: 0 | D26: 79839.163 | E26: 958069.96 | F26: 2475014.1 | G26: 3353244.9 | H26: =SUM(B26:G26) -> 6866168.1
A27: Encofrado en Molde | B27: 0 | C27: 0 | D27: 344766.8 | E27: 1379067.2 | F27: 2413367.6 | G27: 3447668 | H27: =SUM(B27:G27) -> 7584869.6
A28: Acero en Superestructura | B28: 0 | C28: 0 | D28: 333722.19 | E28: 1668611 | F28: 2669777.5 | G28: 3670944.1 | H28: =SUM(B28:G28) -> 8343054.8
A29: Instalaciones Electricas | B29: 0 | C29: 0 | D29: 88641.51 | E29: 354566.04 | F29: 620490.57 | G29: 886415.1 | H29: =SUM(B29:G29) -> 1950113.2
A30: Aguas Blancas | B30: 0 | C30: 0 | D30: 58435.092 | E30: 233740.37 | F30: 409045.65 | G30: 584350.93 | H30: =SUM(B30:G30) -> 1285572
A31: Aguas Residuales | B31: 0 | C31: 0 | D31: 64617.03 | E31: 258468.12 | F31: 452319.21 | G31: 646170.3 | H31: =SUM(B31:G31) -> 1421574.7
A32: Gas | B32: 0 | C32: 0 | D32: 16494.715 | E32: 65978.86 | F32: 115463.01 | G32: 164947.15 | H32: =SUM(B32:G32) -> 362883.73
A33: Albañileria | B33: 0 | C33: 0 | D33: 0 | E33: 0 | F33: 2658473.8 | G33: 2658473.8 | H33: =SUM(B33:G33) -> 5316947.6
... A45: Remates y Limpieza | B45: 0 | C45: 0 | D45: 0 | E45: 0 | F45: 0 | G45: 0 | H45: =SUM(B45:G45) -> 0
A46: TOTAL EDIFICIOS | B46: =SUM(B22:B45) -> 1387237.5 | C46: =SUM(C22:C45) -> 1387237.5 | D46: =SUM(D22:D45) -> 3798163.3 | E46: =SUM(E22:E45) -> 11925251 | F46: =SUM(F22:F45) -> 29783110 | G46: =SUM(G22:G45) -> 38576638 | H46: =SUM(H22:H45) -> 86857637

Sheet Hoja1
E8: 222844.91 | F8: 2449569.8 | G8: 1833923.4 | H8: 2442502.3 | I8: 4340947.8
E9: 2132656.5 | F9: 6421897.4 | G9: 23623624 | H9: 17452542 | I9: 17043612
E11: =SUM(E8:E10) -> 2355501.4 | F11: =SUM(F8:F10) -> 8871467.3 | G11: =SUM(G8:G10) -> 25457547 | H11: =SUM(H8:H10) -> 19895044 | I11: =SUM(I8:I10) -> 21384560
